<!--URDF generated by ONSHAPE BY PTC INC, 1.218-->
<robot name="maxon_motor">
    <link name="body">
        <inertial>
            <mass value="3.13126e-06" />
            <origin xyz="-5.23054e-21 -0.000433745 4.96358e-19" rpy="0 -0 0" />
            <inertia ixx="2.28351e-10" ixy="0" ixz="0" iyy="5.57578e-11" iyz="0" izz="2.28351e-10" />
        </inertial>
        <visual>
            <origin xyz="0 0 0" rpy="0 -0 0" />
            <geometry>
                <mesh filename="package://embr_description/meshes/maxon_motor/meshes/Body.stl" scale="1 1 1" />
            </geometry>
            <material name="0.501961_0.501961_0.501961_0.000000_0.000000">
                <color rgba="0.501961 0.501961 0.501961 1" />
            </material>
        </visual>
    </link>
    <link name="root" />
    <link name="shaft">
        <inertial>
            <mass value="7.23207e-08" />
            <origin xyz="-7.1924e-07 0.0205367 -2.01903e-07" rpy="0 -0 0" />
            <inertia ixx="1.01063e-11" ixy="-1.04551e-15" ixz="0" iyy="2.03495e-14" iyz="0" izz="1.01063e-11" />
        </inertial>
        <visual>
            <origin xyz="0 0.0204 -9.093e-19" rpy="0 -0 0" />
            <geometry>
                <mesh filename="package://embr_description/meshes/maxon_motor/meshes/Shaft.stl" scale="1 1 1" />
            </geometry>
            <material name="0.901961_0.901961_0.901961_0.000000_0.000000">
                <color rgba="0.901961 0.901961 0.901961 1" />
            </material>
        </visual>
    </link>
    <link name="tab_1">
        <inertial>
            <mass value="3.48e-09" />
            <origin xyz="0.0046 0.00435 3.18908e-19" rpy="0 -0 0" />
            <inertia ixx="2.31101e-14" ixy="0" ixz="0" iyy="1.1716e-15" iyz="0" izz="2.19617e-14" />
        </inertial>
        <visual>
            <origin xyz="8.67362e-19 -0.0133 3.18908e-19" rpy="0 -0 0" />
            <geometry>
                <mesh filename="package://embr_description/meshes/maxon_motor/meshes/Tab_1.stl" scale="1 1 1" />
            </geometry>
            <material name="0.917647_0.917647_0.917647_0.000000_0.000000">
                <color rgba="0.917647 0.917647 0.917647 1" />
            </material>
        </visual>
    </link>
    <link name="tab_2">
        <inertial>
            <mass value="3.48e-09" />
            <origin xyz="-0.0046 0.00435 3.08814e-19" rpy="0 -0 0" />
            <inertia ixx="2.31101e-14" ixy="0" ixz="0" iyy="1.1716e-15" iyz="0" izz="2.19617e-14" />
        </inertial>
        <visual>
            <origin xyz="-8.67362e-19 -0.0133 3.08814e-19" rpy="0 -0 0" />
            <geometry>
                <mesh filename="package://embr_description/meshes/maxon_motor/meshes/Tab_2.stl" scale="1 1 1" />
            </geometry>
            <material name="0.917647_0.917647_0.917647_0.000000_0.000000">
                <color rgba="0.917647 0.917647 0.917647 1" />
            </material>
        </visual>
    </link>
    <joint name="fastened_1" type="fixed">
        <origin xyz="0 0.0133 4.33681e-19" rpy="0 -0 0" />
        <axis xyz="-0 -1 -0" />
        <parent link="body" />
        <child link="tab_1" />
    </joint>
    <joint name="fastened_2" type="fixed">
        <origin xyz="0 0.0133 4.33681e-19" rpy="0 -0 0" />
        <axis xyz="-0 -1 -0" />
        <parent link="body" />
        <child link="tab_2" />
    </joint>
    <joint name="fixed_node_to_root_joint" type="fixed">
        <origin xyz="-0.00231638 0.000321054 0.00368762" rpy="0 -0 0" />
        <axis xyz="0 0 1" />
        <parent link="root" />
        <child link="body" />
    </joint>
    <joint name="shaft" type="continuous">
        <origin xyz="-1.30104e-18 -0.0204 8.67362e-19" rpy="0 -0 0" />
        <axis xyz="0 -1 0" />
        <parent link="body" />
        <child link="shaft" />
    </joint>
</robot>
